Workbook
Name EnvironmentSizes: 'V9 Calculator'!$L$18:$L$25
Name MASData: 'Data Source'!$A$28:$G$144

Sheet V9 Calculator
E2: IBM® Maximo® Application Suite Infrastructure Calculator - v9_0_1
E3: ***For GUIDANCE Purpose Only - Actual Deployments Will Vary *** - Enter Inputs in Yellow Cells Only
C5: Enforce 3 Master + 2 Worker Nodes? | F5: Y | H5: 1Users: Users are defined as *concurrent* users when sizing the infrastructure requirements | J5: 2When calculating with i/o points, the total is equal to the product of the following three dimensions: 1) Number of devices 2) Number of data points sent in each message 3) Number of messages sent per minute per device | M5: 3To calculate Predict Data Points, Use the "Predict Data Points" tab | O5: 4Existing JVMs Deployed with Maximo EAM v7.6.1.x If both JVMs and Users are defined, the calculation will use the larger of the two outcomes.
C6: Installing into Existing OpenShift? | F6: N
C7: Install Manage w/Existing Database? | F7: N
C8: Install Monitor w/Existing Database? | F8: N
C9: Exclude CP4D DB2 Allocations? | F9: N
C10: Isolate DB2 Databases on Single Server? | F10: Y
C11: Isolate Visual Inspection GPU Nodes? | F11: Y
C12: Number of Development Environments: | F12: 1 | H12: Additional Sizing Information Links
C13: Enforce Dev DBStorage = Prod DBStorag? | F13: N | H13: MAS Performance / Sizing Link | M13: vCPU | N13: Memory (GiB) | O13: File Storage (GiB) | P13: DB2 Storage (GiB) | Q13: GPU
C14: Add 20% Capacity for Resilency? | F14: N | H14: OCP Compute Nodes Sizing Guidance Link | L14: =IF(F14="Y","Additional 20% Capacity Added: ","") | M14: =IF(F14="Y",ROUNDUP((M26+M37+M44)*0.2,0),0) -> 0 | N14: =IF(F14="Y",ROUNDUP((N26+N37+N44)*0.2,0),0) -> 0
L15: Production Cluster TOTALS: | M15: =M14+M26+M37+M44 -> 41 | N15: =N14+N26+N37+N44 -> 162 | O15: =O26+O37+O44 -> 1050 | P15: =P26+P37+P44 -> 300 | Q15: =P26 -> 2
E16: Calculations | G16: Primary | I16: Secondary (Optional) | L16: OpenShift Master Node TOTALS: | M16: ='Data Source'!D26 -> 12 | N16: ='Data Source'!E26 -> 48 | O16: ='Data Source'!F26 -> 360 | P16: 0 | Q16: 0
F17: Use (Y/N) | G17: Size Metric | H17: Quantity | I17: Size Metric | J17: Quantity | L17: Application Sizing | M17: vCPU | N17: Memory (GiB) | O17: File Storage (GiB) | P17: GPUs
B18: Selections | D18: Applications | E18: Manage | F18: Y | G18: UI JVMs4 | H18: 2 | I18: Users1 | J18: 0 | L18: =E18&" - "&IF(F18="Y","Calculated ","Not Selected ") -> Manage - Calculated | M18: =IF(ISERROR(VLOOKUP(L18,MASData,2,FALSE)),0,VLOOKUP(L18,MASData,2,FALSE)) -> 3.5 | N18: =IF(ISERROR(VLOOKUP(L18,MASData,3,FALSE)),0,VLOOKUP(L18,MASData,3,FALSE)) -> 19 | O18: =IF(ISERROR(VLOOKUP(L18,MASData,4,FALSE)),0,VLOOKUP(L18,MASData,4,FALSE)) -> 0
B19: Y | E19: Health | F19: N | I19: Users1 | J19: 0 | L19: =E19&" - "&IF(F19="Y","Calculated ","Not Selected ") -> Health - Not Selected | M19: =IF(ISERROR(VLOOKUP(L19,MASData,2,FALSE)),0,VLOOKUP(L19,MASData,2,FALSE)) -> 0 | N19: =IF(ISERROR(VLOOKUP(L19,MASData,3,FALSE)),0,VLOOKUP(L19,MASData,3,FALSE)) -> 0 | O19: =IF(ISERROR(VLOOKUP(L19,MASData,4,FALSE)),0,VLOOKUP(L19,MASData,4,FALSE)) -> 0
B20: N | E20: Monitor | F20: N | G20: i/o points2 | H20: 2400 | I20: Users1 | J20: 0 | L20: =E20&" - "&'Data Source'!P7 -> Monitor - Not Selected | M20: =IF(ISERROR(VLOOKUP(L20,MASData,2,FALSE)),0,VLOOKUP(L20,MASData,2,FALSE)) -> 0 | N20: =IF(ISERROR(VLOOKUP(L20,MASData,3,FALSE)),0,VLOOKUP(L20,MASData,3,FALSE)) -> 0 | O20: =IF(ISERROR(VLOOKUP(L20,MASData,4,FALSE)),0,VLOOKUP(L20,MASData,4,FALSE)) -> 0
E21: Predict | F21: N | G21: Data Points3 | H21: ='Predict Data Points'!D21 -> 2628000 | I21: =IF(F21="Y","<--- Predict Data Points Tab","") | L21: =E21&" - "&IF(AND(F21="Y",OR(F19="N",F20="N")),"Requires Health & Monitor ",'Data Source'!P11) -> Predict - Not Selected | M21: =IF(AND(F21="Y",OR(F19="N",F20="N")),"Error",IF(ISERROR(VLOOKUP(L21,MASData,2,FALSE)),0,VLOOKUP(L21,MASData,2,FALSE))) -> 0 | N21: =IF(AND(F21="Y",OR(F19="N",F20="N")),"Error",IF(ISERROR(VLOOKUP(L21,MASData,3,FALSE)),0,VLOOKUP(L21,MASData,3,FALSE))) -> 0 | O21: =IF(AND(F21="Y",OR(F19="N",F20="N")),"Error",IF(ISERROR(VLOOKUP(L21,MASData,4,FALSE)),0,VLOOKUP(L21,MASData,4,FALSE))) -> 0
B22: Isolate GPU? | E22: Maximo IT | F22: N | G22: UI JVMs4 | H22: 0 | I22: =IF(AND(F18="Y",F22="Y"),"IT Only + Users","Concurrent Users") -> Concurrent Users | J22: 0 | L22: =E22&" - "&IF(F22="Y","Calculated ","Not Selected ") -> Maximo IT - Not Selected | M22: =IF(ISERROR(VLOOKUP(L22,MASData,2,FALSE)),0,VLOOKUP(L22,MASData,2,FALSE)) -> 0 | N22: =IF(ISERROR(VLOOKUP(L22,MASData,3,FALSE)),0,VLOOKUP(L22,MASData,3,FALSE)) -> 0 | O22: =IF(ISERROR(VLOOKUP(L22,MASData,4,FALSE)),0,VLOOKUP(L22,MASData,4,FALSE)) -> 0
B23: =IF(AND(COUNTIF(F18:F25,"Y")>1,F23="Y",F11="Y"),"Y","N") -> Y | E23: Visual Inspection | F23: Y | G23: Users1 | H23: 0 | L23: =E23&" - "&'Data Source'!P14 -> Visual Inspection - Xsmall/Min | M23: =IF(ISERROR(VLOOKUP(L23,MASData,2,FALSE)),0,VLOOKUP(L23,MASData,2,FALSE)) -> 4 | N23: =IF(ISERROR(VLOOKUP(L23,MASData,3,FALSE)),0,VLOOKUP(L23,MASData,3,FALSE)) -> 64 | O23: =IF(ISERROR(VLOOKUP(L23,MASData,4,FALSE)),0,VLOOKUP(L23,MASData,4,FALSE)) -> 115 | P23: =IF(ISERROR(VLOOKUP(L23,MASData,6,FALSE)),0,VLOOKUP(L23,MASData,6,FALSE)) -> 2
E24: Assist | F24: N | G24: Users1 | H24: 0 | L24: =E24&" - "&'Data Source'!P15 -> Assist - Not Selected | M24: =IF(ISERROR(VLOOKUP(L24,MASData,2,FALSE)),0,VLOOKUP(L24,MASData,2,FALSE)) -> 0 | N24: =IF(ISERROR(VLOOKUP(L24,MASData,3,FALSE)),0,VLOOKUP(L24,MASData,3,FALSE)) -> 0 | O24: =IF(ISERROR(VLOOKUP(L24,MASData,4,FALSE)),0,VLOOKUP(L24,MASData,4,FALSE)) -> 0
B25: CP4D Needed? | E25: Optimizer | F25: N | G25: Users1 | H25: 0 | L25: =E25&" - "&'Data Source'!P22 -> Optimizer - Not Selected | M25: =IF(ISERROR(VLOOKUP(L25,MASData,2,FALSE)),0,VLOOKUP(L25,MASData,2,FALSE)) -> 0 | N25: =IF(ISERROR(VLOOKUP(L25,MASData,3,FALSE)),0,VLOOKUP(L25,MASData,3,FALSE)) -> 0 | O25: =IF(ISERROR(VLOOKUP(L25,MASData,4,FALSE)),0,VLOOKUP(L25,MASData,4,FALSE)) -> 0
B26: =IF(OR(AND($F$18="Y",$F$7="N",$F$9="N"),AND($F$19="Y",$F$7="N",$F$9="N"),AND($F$20="Y",$F$8="N",$F$9="N"),AND($F$22="Y",$F$7="N",$F$9="N"),$F$21="Y"),"Y","N") -> Y | L26: Total Application Quantities: | M26: =SUM(M18:M25) -> 7.5 | N26: =SUM(N18:N25) -> 83 | O26: =SUM(O18:O25) -> 115 | P26: =SUM(P18:P25) -> 2
B28: Isolate DB? | L28: Additional Application Sizing | M28: vCPU | N28: Memory (GiB) | O28: File Storage (GiB) | P28: DB2 Storage (GiB)
B29: =IF(AND(OR(F7="N",F8="N"),F10="Y",COUNTIF(F18:F20,"Y")>0),"Y","N") -> Y | G29: Additional Manage JVM Options | L29: =E18&"/"&E19&"/"&"IT DB2 - "&'Data Source'!B24 -> Manage/Health/IT DB2 - Xsmall/Min | M29: =IF(F7="Y",0,IF(ISERROR(VLOOKUP(L29,MASData,2,FALSE)),0,VLOOKUP(L29,MASData,2,FALSE))) -> 12 | N29: =IF(F7="Y",0,IF(ISERROR(VLOOKUP(L29,MASData,3,FALSE)),0,VLOOKUP(L29,MASData,3,FALSE))) -> 48 | O29: =IF(ISERROR(VLOOKUP(L29,MASData,4,FALSE)),0,VLOOKUP(L29,MASData,4,FALSE)) -> 0 | P29: =IF(ISERROR(VLOOKUP(L29,MASData,5,FALSE)),0,VLOOKUP(L29,MASData,5,FALSE)) -> 298
G30: Deploy Cognos? | H30: =IF($F$18="Y","Manage Specific JVM Requirements","") -> Manage Specific JVM Requirements | L30: =E20&" DB2 - "&'Data Source'!P7 -> Monitor DB2 - Not Selected | M30: =IF(F8="Y",0,IF(ISERROR(VLOOKUP(L30,MASData,2,FALSE)),0,VLOOKUP(L30,MASData,2,FALSE))) -> 0 | N30: =IF(F8="Y",0,IF(ISERROR(VLOOKUP(L30,MASData,3,FALSE)),0,VLOOKUP(L30,MASData,3,FALSE))) -> 0 | O30: =IF(F8="Y",0,IF(ISERROR(VLOOKUP(L30,MASData,4,FALSE)),0,VLOOKUP(L30,MASData,4,FALSE))) -> 0 | P30: =IF(F8="Y",0,IF(ISERROR(VLOOKUP(L30,MASData,5,FALSE)),0,VLOOKUP(L30,MASData,5,FALSE))) -> 0
B31: Main Conf | H31: =IF($F$18="Y","MIF","") -> MIF | I31: =IF($F$18="Y","Reporting","") -> Reporting | J31: =IF($F$18="Y","Crontask","") -> Crontask | L31: =E18&" - "&IF(F18="Y", "(MIF, Rprt, Crontask) + Cognos + JMS ","Not Selected ") -> Manage - (MIF, Rprt, Crontask) + Cognos + JMS | M31: =IF(ISERROR(VLOOKUP(L31,MASData,2,FALSE)),0,VLOOKUP(L31,MASData,2,FALSE))+IF(F18="N",0,IF(ISERROR(VLOOKUP("Cognos",MASData,2,FALSE)),0,VLOOKUP("Cognos",MASData,2,FALSE))) -> 0 | N31: =IF(ISERROR(VLOOKUP(L31,MASData,3,FALSE)),0,VLOOKUP(L31,MASData,3,FALSE))+IF(F18="N",0,IF(ISERROR(VLOOKUP("Cognos",MASData,3,FALSE)),0,VLOOKUP("Cognos",MASData,3,FALSE))) -> 0 | O31: =IF(ISERROR(VLOOKUP(L31,MASData,4,FALSE)),0,VLOOKUP(L31,MASData,4,FALSE))+IF(F18="N",0,IF(ISERROR(VLOOKUP("Cognos",MASData,4,FALSE)),0,VLOOKUP("Cognos",MASData,4,FALSE))) -> 0 | P31: =IF(ISERROR(VLOOKUP(L31,MASData,5,FALSE)),0,VLOOKUP(L31,MASData,5,FALSE))+IF(F18="N",0,IF(ISERROR(VLOOKUP("Cognos",MASData,5,FALSE)),0,VLOOKUP("Cognos",MASData,5,FALSE))) -> 0
B32: =IF(AND(B29="N",B23="N"),M55,IF(AND(B29="Y",B23="Y"),M55-M29-M30-M23-(F12*'Development Detailed Report'!C19)-(F12*'Development Detailed Report'!C18)-(F12*'Development Detailed Report'!C12),IF(B23="Y",M55-M23-(F12*'Development Detailed Report'!C12),M55-M29-M30-(F12*'Development Detailed Report'!C19)-(F12*'Development Detailed Report'!C18)))) -> 48.5 | G32: N | H32: 0 | I32: 0 | J32: 0 | L32: =E18&" - "&IF(F18="Y", "Industry Solutions ","Not Selected ") -> Manage - Industry Solutions | M32: =IF(AND(F18="Y",OR(J34="Y",I35="Y",H35="Y",G35="Y")),IF(ISERROR(VLOOKUP(L32,MASData,2,FALSE)),0,VLOOKUP(L32,MASData,2,FALSE)),0) -> 0 | N32: =IF(AND(F18="Y",OR(J34="Y",I35="Y",H35="Y",G35="Y")),IF(ISERROR(VLOOKUP(L32,MASData,3,FALSE)),0,VLOOKUP(L32,MASData,3,FALSE)),0) -> 0 | O32: =IF(AND(F18="Y",OR(J34="Y",I35="Y",H35="Y",G35="Y")),IF(ISERROR(VLOOKUP(L32,MASData,4,FALSE)),0,VLOOKUP(L32,MASData,4,FALSE)),0) -> 0 | P32: =IF(AND(F18="Y",OR(J34="Y",I35="Y",H35="Y",G35="Y")),IF(ISERROR(VLOOKUP(L32,MASData,5,FALSE)),0,VLOOKUP(L32,MASData,5,FALSE)),0) -> 0
B33: =IF(AND(B29="N",B23="N"),N55,IF(AND(B29="Y",B23="Y"),N55-N29-N30-N23-(F12*'Development Detailed Report'!D19)-(F12*'Development Detailed Report'!D18)-(F12*'Development Detailed Report'!D12),IF(B23="Y",N55-N23-(F12*'Development Detailed Report'!D12),N55-N29-N30-(F12*'Development Detailed Report'!D19)-(F12*'Development Detailed Report'!D18)))) -> 99 | G33: Industry Solutions | J33: Add JMS? | L33: ="Watson Studio - "&'Data Source'!S51 -> Watson Studio - Not Selected | M33: =IF(OR(M21="Error",M22="Error"),"Error",IF(ISERROR(VLOOKUP(L33,MASData,2,FALSE)),0,VLOOKUP(L33,MASData,2,FALSE))) -> 0 | N33: =IF(OR(N21="Error",N22="Error"),"Error",IF(ISERROR(VLOOKUP(L33,MASData,3,FALSE)),0,VLOOKUP(L33,MASData,3,FALSE))) -> 0 | O33: =IF(OR(O21="Error",O22="Error"),"Error",IF(ISERROR(VLOOKUP(L33,MASData,4,FALSE)),0,VLOOKUP(L33,MASData,4,FALSE))) -> 0 | P33: 0
B34: =IF(B23="N",Q55,Q55-P23-(F12*'Development Detailed Report'!F12)) -> 0 | G34: Aviation/ACM? | J34: N | L34: ="Watson ML - "&'Data Source'!P11 -> Watson ML - Not Selected | M34: =IF(M21="Error","Error",IF(ISERROR(VLOOKUP(L34,MASData,2,FALSE)),0,VLOOKUP(L34,MASData,2,FALSE))) -> 0 | N34: =IF(N21="Error","Error",IF(ISERROR(VLOOKUP(L34,MASData,3,FALSE)),0,VLOOKUP(L34,MASData,3,FALSE))) -> 0 | O34: =IF(O21="Error","Error",IF(ISERROR(VLOOKUP(L34,MASData,4,FALSE)),0,VLOOKUP(L34,MASData,4,FALSE))) -> 0 | P34: 0
G35: N | L35: ="Kafka - "&'Data Source'!P7 -> Kafka - Not Selected | M35: =IF(ISERROR(VLOOKUP(L35,MASData,2,FALSE)),0,VLOOKUP(L35,MASData,2,FALSE)) -> 0 | N35: =IF(ISERROR(VLOOKUP(L35,MASData,3,FALSE)),0,VLOOKUP(L35,MASData,3,FALSE)) -> 0 | O35: =IF(ISERROR(VLOOKUP(L35,MASData,4,FALSE)),0,VLOOKUP(L35,MASData,4,FALSE)) -> 0 | P35: 0
B36: MVI Conf | L36: ="CouchDB - "&'Data Source'!P15 -> CouchDB - Not Selected | M36: =IF(ISERROR(VLOOKUP(L36,MASData,2,FALSE)),0,VLOOKUP(L36,MASData,2,FALSE)) -> 0 | N36: =IF(ISERROR(VLOOKUP(L36,MASData,3,FALSE)),0,VLOOKUP(L36,MASData,3,FALSE)) -> 0 | O36: =IF(ISERROR(VLOOKUP(L36,MASData,4,FALSE)),0,VLOOKUP(L36,MASData,4,FALSE)) -> 0 | P36: 0
B37: =IF(B23="N",0,M23+(F12*'Development Detailed Report'!C12)) -> 8 | L37: Total Additional Application Quantities: | M37: =SUM(M29:M36) -> 12 | N37: =SUM(N29:N36) -> 48 | O37: =SUM(O29:O36) -> 0 | P37: =SUM(P29:P36) -> 298
B38: =IF(B23="N",0,N23+(F12*'Development Detailed Report'!D12)) -> 128
B39: =IF(B23="N",0,Q55) -> 3 | L39: Cluster Wide Allocations | M39: vCPU | N39: Memory (GiB) | O39: File Storage (GiB) | P39: DB2 Storage (GiB)
L40: ="MongoDB - "&'Data Source'!S35 -> MongoDB - Xsmall/Min | M40: =IF(ISERROR(VLOOKUP(L40,MASData,2,FALSE)),0,VLOOKUP(L40,MASData,2,FALSE)) -> 1.5 | N40: =IF(ISERROR(VLOOKUP(L40,MASData,3,FALSE)),0,VLOOKUP(L40,MASData,3,FALSE)) -> 3 | O40: =IF(ISERROR(VLOOKUP(L40,MASData,4,FALSE)),0,VLOOKUP(L40,MASData,4,FALSE)) -> 20 | P40: =IF(ISERROR(VLOOKUP(L40,MASData,5,FALSE)),0,VLOOKUP(L40,MASData,5,FALSE)) -> 0
B41: DB Conf | L41: =IF(COUNTIF($F$18:$F$25,"Y")>=1,"MAS Core ","MAS Core - Not Selected ") -> MAS Core | M41: =IF(ISERROR(VLOOKUP(L41,MASData,2,FALSE)),0,VLOOKUP(L41,MASData,2,FALSE)) -> 2 | N41: =IF(ISERROR(VLOOKUP(L41,MASData,3,FALSE)),0,VLOOKUP(L41,MASData,3,FALSE)) -> 2 | O41: =IF(ISERROR(VLOOKUP(L41,MASData,4,FALSE)),0,VLOOKUP(L41,MASData,4,FALSE)) -> 20 | P41: =IF(ISERROR(VLOOKUP(L41,MASData,5,FALSE)),0,VLOOKUP(L41,MASData,5,FALSE)) -> 0
B42: =IF(B29="N",0,M29+M30+(F12*'Development Detailed Report'!C18)+(F12*'Development Detailed Report'!C19)) -> 18 | L42: =IF(COUNTIF($F$18:$F$25,"Y")>=1,"OpenShift Worker Nodes - "&'Data Source'!S35,"OpenShift Worker Nodes - Not Selected ") -> OpenShift Worker Nodes - Xsmall/Min | M42: =IF(ISERROR(VLOOKUP(L42,MASData,2,FALSE)),0,VLOOKUP(L42,MASData,2,FALSE)) -> 4 | N42: =IF(ISERROR(VLOOKUP(L42,MASData,3,FALSE)),0,VLOOKUP(L42,MASData,3,FALSE)) -> 16 | O42: =IF(ISERROR(VLOOKUP(L42,MASData,4,FALSE)),0,VLOOKUP(L42,MASData,4,FALSE)) -> 240 | P42: =IF(ISERROR(VLOOKUP(L42,MASData,5,FALSE)),0,VLOOKUP(L42,MASData,5,FALSE)) -> 0
B43: =IF(B29="N",0,N29+N30+(F12*'Development Detailed Report'!D18)+(F12*'Development Detailed Report'!D19)) -> 72 | L43: =IF(B26="Y","CP4D Base ","CP4D Base - Not Required ") -> CP4D Base | M43: =IF($B$26="Y",IF(ISERROR(VLOOKUP(L43,MASData,2,FALSE)),0,VLOOKUP(L43,MASData,2,FALSE)),0) -> 14 | N43: =IF(OR(AND($F$18="Y",$F$7="N"),AND($F$19="Y",$F$7="N"),AND($F$20="Y",$F$8="N"),$F$21="Y",$F$22="Y",$F$24="Y"),IF(ISERROR(VLOOKUP(L43,MASData,3,FALSE)),0,VLOOKUP(L43,MASData,3,FALSE)),0) -> 10 | O43: =IF(OR(AND($F$18="Y",$F$7="N"),AND($F$19="Y",$F$7="N"),AND($F$20="Y",$F$8="N"),$F$21="Y",$F$22="Y",$F$24="Y"),IF(ISERROR(VLOOKUP(L43,MASData,4,FALSE)),0,VLOOKUP(L43,MASData,4,FALSE)),0) -> 655 | P43: =IF(OR(AND($F$18="Y",$F$7="N"),AND($F$19="Y",$F$7="N"),AND($F$20="Y",$F$8="N"),$F$21="Y",$F$22="Y",$F$24="Y"),IF(ISERROR(VLOOKUP(L43,MASData,5,FALSE)),0,VLOOKUP(L43,MASData,5,FALSE)),0) -> 0
...

Sheet Production Detailed Report
B2: =IF('V9 Calculator'!F14="Y","Production Environment Calculation Details - 20% Additional Capacity Reflected ONLY in V9 Calculator Sheet","Production Environment Calculation Details") -> Production Environment Calculation Details
D5: ='V9 Calculator'!L18 -> Manage - Calculated | E5: ='V9 Calculator'!L19 -> Health - Not Selected | F5: ='V9 Calculator'!L20 -> Monitor - Not Selected | G5: ='V9 Calculator'!L21 -> Predict - Not Selected | H5: ='V9 Calculator'!L22 -> Maximo IT - Not Selected | I5: ='V9 Calculator'!L23 -> Visual Inspection - Xsmall/Min | J5: ='V9 Calculator'!L24 -> Assist - Not Selected | K5: ='V9 Calculator'!L25 -> Optimizer - Not Selected
B6: vCPUs | D6: ='V9 Calculator'!E18 -> Manage | E6: ='V9 Calculator'!E19 -> Health | F6: ='V9 Calculator'!E20 -> Monitor | G6: ='V9 Calculator'!E21 -> Predict | H6: ='V9 Calculator'!E22 -> Maximo IT | I6: ='V9 Calculator'!E23 -> Visual Inspection | J6: ='V9 Calculator'!E24 -> Assist | K6: ='V9 Calculator'!E25 -> Optimizer | L6: TOTALS
B7: Core Application vCPUs -----> | D7: =IF(ISERROR(VLOOKUP(D5,MASData,2,FALSE)),0,VLOOKUP(D5,MASData,2,FALSE)) -> 3.5 | E7: =IF(ISERROR(VLOOKUP(E5,MASData,2,FALSE)),0,VLOOKUP(E5,MASData,2,FALSE)) -> 0 | F7: =IF(ISERROR(VLOOKUP(F5,MASData,2,FALSE)),0,VLOOKUP(F5,MASData,2,FALSE)) -> 0 | G7: =IF(ISERROR(VLOOKUP(G5,MASData,2,FALSE)),0,VLOOKUP(G5,MASData,2,FALSE)) -> 0 | H7: =IF(ISERROR(VLOOKUP(H5,MASData,2,FALSE)),0,VLOOKUP(H5,MASData,2,FALSE)) -> 0 | I7: =IF(ISERROR(VLOOKUP(I5,MASData,2,FALSE)),0,VLOOKUP(I5,MASData,2,FALSE)) -> 4 | J7: =IF(ISERROR(VLOOKUP(J5,MASData,2,FALSE)),0,VLOOKUP(J5,MASData,2,FALSE)) -> 0 | K7: =IF(ISERROR(VLOOKUP(K5,MASData,2,FALSE)),0,VLOOKUP(K5,MASData,2,FALSE)) -> 0 | L7: =SUM(D7:K7) -> 7.5
B9: ='V9 Calculator'!L29 -> Manage/Health/IT DB2 - Xsmall/Min | D9: =IF(N9="Y",'V9 Calculator'!M29,0) -> 12 | E9: =IF(AND(N10="Y",N9="N"),'V9 Calculator'!M29,0) -> 0 | F9: 0 | G9: 0 | H9: =IF(AND(N9="N",N10="N",N12="Y"),'V9 Calculator'!M29,0) -> 0 | I9: 0 | J9: 0 | K9: 0 | N9: ='V9 Calculator'!F18 -> Y | O9: Manage
B10: ='V9 Calculator'!L30 -> Monitor DB2 - Not Selected | D10: 0 | E10: 0 | F10: =IF(ISERROR(VLOOKUP(B10,MASData,2,FALSE)),0,VLOOKUP(B10,MASData,2,FALSE)) -> 0 | G10: 0 | H10: 0 | I10: 0 | J10: 0 | K10: 0 | N10: ='V9 Calculator'!F19 -> N | O10: Health
B11: ='V9 Calculator'!L31 -> Manage - (MIF, Rprt, Crontask) + Cognos + JMS | D11: ='V9 Calculator'!M31 -> 0 | E11: 0 | F11: 0 | G11: 0 | H11: 0 | I11: 0 | J11: 0 | K11: 0 | N11: ='V9 Calculator'!F20 -> N | O11: Monitor
B12: ='V9 Calculator'!L32 -> Manage - Industry Solutions | D12: ='V9 Calculator'!M32 -> 0 | E12: 0 | F12: 0 | G12: 0 | H12: 0 | I12: 0 | J12: 0 | K12: 0 | N12: ='V9 Calculator'!F22 -> N | O12: Maximo IT
B13: ='V9 Calculator'!L33 -> Watson Studio - Not Selected | D13: 0 | E13: 0 | F13: 0 | G13: =IF(OR(N13="Y",AND(N13="Y",N14="Y")),'V9 Calculator'!M33,0) -> 0 | H13: =IF(N13="Y",0,'V9 Calculator'!M33) -> 0 | I13: 0 | J13: 0 | K13: 0 | N13: ='V9 Calculator'!F21 -> N | O13: Predict
B14: ='V9 Calculator'!L34 -> Watson ML - Not Selected | D14: 0 | E14: 0 | F14: 0 | G14: ='V9 Calculator'!M34 -> 0 | H14: 0 | I14: 0 | J14: 0 | K14: 0 | N14: ='V9 Calculator'!F23 -> Y | O14: Visual Inspection
B15: ='V9 Calculator'!L35 -> Kafka - Not Selected | D15: 0 | E15: 0 | F15: ='V9 Calculator'!M35 -> 0 | G15: 0 | H15: 0 | I15: 0 | J15: 0 | K15: 0 | N15: ='V9 Calculator'!F24 -> N | O15: Assist
B16: ='V9 Calculator'!L36 -> CouchDB - Not Selected | D16: 0 | E16: 0 | F16: 0 | G16: 0 | H16: 0 | I16: 0 | J16: =IF(ISERROR(VLOOKUP(B16,MASData,2,FALSE)),0,VLOOKUP(B16,MASData,2,FALSE)) -> 0 | K16: 0 | N16: ='V9 Calculator'!F25 -> N | O16: Optimizer
B17: Additional Applications vCPU Totals: | L17: =SUM(D9:K16) -> 12
B19: ='V9 Calculator'!L40 -> MongoDB - Xsmall/Min | D19: ='V9 Calculator'!M40 -> 1.5
B20: ='V9 Calculator'!L41 -> MAS Core | D20: ='V9 Calculator'!M41 -> 2
B21: ='V9 Calculator'!L42 -> OpenShift Worker Nodes - Xsmall/Min | D21: ='V9 Calculator'!M42 -> 4
B22: ='V9 Calculator'!L43 -> CP4D Base | D22: ='V9 Calculator'!M43 -> 14
B23: Cluster Wide vCPU Totals: | L23: =SUM(D19:K22) -> 21.5
B24: TOTAL vCPUs: | L24: =L23+L17+L7 -> 41
B26: Memory (GiB) | D26: =D6 -> Manage | E26: =E6 -> Health | F26: =F6 -> Monitor | G26: =G6 -> Predict | H26: =H6 -> Maximo IT | I26: =I6 -> Visual Inspection | J26: =J6 -> Assist | K26: =K6 -> Optimizer | L26: TOTALS
B27: Core Application Memory (GiB) -----> | D27: =IF(ISERROR(VLOOKUP(D5,MASData,3,FALSE)),0,VLOOKUP(D5,MASData,3,FALSE)) -> 19 | E27: =IF(ISERROR(VLOOKUP(E5,MASData,3,FALSE)),0,VLOOKUP(E5,MASData,3,FALSE)) -> 0 | F27: =IF(ISERROR(VLOOKUP(F5,MASData,3,FALSE)),0,VLOOKUP(F5,MASData,3,FALSE)) -> 0 | G27: =IF(ISERROR(VLOOKUP(G5,MASData,3,FALSE)),0,VLOOKUP(G5,MASData,3,FALSE)) -> 0 | H27: =IF(ISERROR(VLOOKUP(H5,MASData,3,FALSE)),0,VLOOKUP(H5,MASData,3,FALSE)) -> 0 | I27: =IF(ISERROR(VLOOKUP(I5,MASData,3,FALSE)),0,VLOOKUP(I5,MASData,3,FALSE)) -> 64 | J27: =IF(ISERROR(VLOOKUP(J5,MASData,3,FALSE)),0,VLOOKUP(J5,MASData,3,FALSE)) -> 0 | K27: =IF(ISERROR(VLOOKUP(K5,MASData,3,FALSE)),0,VLOOKUP(K5,MASData,3,FALSE)) -> 0 | L27: =SUM(D27:K27) -> 83
B29: =B9 -> Manage/Health/IT DB2 - Xsmall/Min | D29: =IF(N9="Y",'V9 Calculator'!N29,0) -> 48 | E29: =IF(AND(N10="Y",N9="N"),'V9 Calculator'!N29,0) -> 0 | F29: 0 | G29: 0 | H29: =IF(AND(N9="N",N10="N",N12="Y"),'V9 Calculator'!N29,0) -> 0 | I29: 0 | J29: 0 | K29: 0
B30: =B10 -> Monitor DB2 - Not Selected | D30: 0 | E30: 0 | F30: =IF(ISERROR(VLOOKUP(B30,MASData,3,FALSE)),0,VLOOKUP(B30,MASData,3,FALSE)) -> 0 | G30: 0 | H30: 0 | I30: 0 | J30: 0 | K30: 0
B31: =B11 -> Manage - (MIF, Rprt, Crontask) + Cognos + JMS | D31: ='V9 Calculator'!N31 -> 0 | E31: 0 | F31: 0 | G31: 0 | H31: 0 | I31: 0 | J31: 0 | K31: 0
B32: =B12 -> Manage - Industry Solutions | D32: ='V9 Calculator'!N32 -> 0 | E32: 0 | F32: 0 | G32: 0 | H32: 0 | I32: 0 | J32: 0 | K32: 0
B33: =B13 -> Watson Studio - Not Selected | D33: 0 | E33: 0 | F33: 0 | G33: =IF(OR(N13="Y",AND(N13="Y",N14="Y")),'V9 Calculator'!N33,0) -> 0 | H33: =IF(N13="Y",0,'V9 Calculator'!N33) -> 0 | I33: 0 | J33: 0 | K33: 0
B34: =B14 -> Watson ML - Not Selected | D34: 0 | E34: 0 | F34: 0 | G34: ='V9 Calculator'!N34 -> 0 | H34: 0 | I34: 0 | J34: 0 | K34: 0
B35: =B15 -> Kafka - Not Selected | D35: 0 | E35: 0 | F35: ='V9 Calculator'!N35 -> 0 | G35: 0 | H35: 0 | I35: 0 | J35: 0 | K35: 0
B36: =B16 -> CouchDB - Not Selected | D36: 0 | E36: 0 | F36: 0 | G36: 0 | H36: 0 | I36: 0 | J36: =IF(ISERROR(VLOOKUP(B36,MASData,3,FALSE)),0,VLOOKUP(B36,MASData,3,FALSE)) -> 0 | K36: 0
B37: Additional Applications Memory (GiB) Totals: | L37: =SUM(D29:K36) -> 48
B39: =B19 -> MongoDB - Xsmall/Min | D39: ='V9 Calculator'!N40 -> 3
B40: =B20 -> MAS Core | D40: ='V9 Calculator'!N41 -> 2
B41: =B21 -> OpenShift Worker Nodes - Xsmall/Min | D41: ='V9 Calculator'!N42 -> 16
B42: =B22 -> CP4D Base | D42: ='V9 Calculator'!N43 -> 10
B43: Cluster Wide Memory (GiB) Totals: | L43: =SUM(D39:K42) -> 31
B44: TOTAL Memory (GiB): | L44: =L43+L37+L27 -> 162
B46: Storage (GiB) | D46: =D26 -> Manage | E46: =E26 -> Health | F46: =F26 -> Monitor | G46: =G26 -> Predict | H46: =H26 -> Maximo IT | I46: =I26 -> Visual Inspection | J46: =J26 -> Assist | K46: =K26 -> Optimizer | L46: TOTALS
B47: Core Applications File System (GiB) -----> | D47: =IF(ISERROR(VLOOKUP(D5,MASData,4,FALSE)),0,VLOOKUP(D5,MASData,4,FALSE)) -> 0 | E47: =IF(ISERROR(VLOOKUP(E5,MASData,4,FALSE)),0,VLOOKUP(E5,MASData,4,FALSE)) -> 0 | F47: =IF(ISERROR(VLOOKUP(F5,MASData,4,FALSE)),0,VLOOKUP(F5,MASData,4,FALSE)) -> 0 | G47: =IF(ISERROR(VLOOKUP(G5,MASData,4,FALSE)),0,VLOOKUP(G5,MASData,4,FALSE)) -> 0 | H47: =IF(ISERROR(VLOOKUP(H5,MASData,4,FALSE)),0,VLOOKUP(H5,MASData,4,FALSE)) -> 0 | I47: =IF(ISERROR(VLOOKUP(I5,MASData,4,FALSE)),0,VLOOKUP(I5,MASData,4,FALSE)) -> 115 | J47: =IF(ISERROR(VLOOKUP(J5,MASData,4,FALSE)),0,VLOOKUP(J5,MASData,4,FALSE)) -> 0 | K47: =IF(ISERROR(VLOOKUP(K5,MASData,4,FALSE)),0,VLOOKUP(K5,MASData,4,FALSE)) -> 0 | L47: =SUM(D47:K47) -> 115
B49: =B29 -> Manage/Health/IT DB2 - Xsmall/Min | D49: =IF(N9="Y",'V9 Calculator'!P29,0) -> 298 | E49: =IF(AND(N10="Y",N9="N"),'V9 Calculator'!P29,0) -> 0 | F49: 0 | G49: 0 | H49: =IF(AND(N9="N",N10="N",N12="Y"),'V9 Calculator'!P29,0) -> 0 | I49: 0 | J49: 0 | K49: 0
B50: =B30 -> Monitor DB2 - Not Selected | D50: 0 | E50: 0 | F50: ='V9 Calculator'!P30 -> 0 | G50: 0 | H50: 0 | I50: 0 | J50: 0 | K50: 0
...

Sheet Development Detailed Report
B1: Development Environment Calculation Details
B4: Total Development Clusters Entered | C4: ='V9 Calculator'!F12 -> 1
B6: Application Sizing | C6: vCPU | D6: Memory (GiB) | E6: File Storage (GiB) | F6: GPUs
B7: =IF(H7="Y","Manage - Dev ","Manage - Not Selected ") -> Manage - Dev | C7: =IF(ISERROR(VLOOKUP(B7,MASData,2,FALSE)),0,VLOOKUP(B7,MASData,2,FALSE)) -> 2 | D7: =IF(ISERROR(VLOOKUP(B7,MASData,3,FALSE)),0,VLOOKUP(B7,MASData,3,FALSE)) -> 18 | E7: =IF(ISERROR(VLOOKUP(B7,MASData,4,FALSE)),0,VLOOKUP(B7,MASData,4,FALSE)) -> 0 | H7: =IF($C$4=0,"N",'V9 Calculator'!F18) -> Y | I7: Manage
B8: =IF(H8="Y","Health - Dev ","Health - Not Selected ") -> Health - Not Selected | C8: =IF(H7="Y",0,IF(ISERROR(VLOOKUP(B8,MASData,2,FALSE)),0,VLOOKUP(B8,MASData,2,FALSE))) -> 0 | D8: =IF(H7="Y",0,IF(ISERROR(VLOOKUP(B8,MASData,3,FALSE)),0,VLOOKUP(B8,MASData,3,FALSE))) -> 0 | E8: =IF(H7="Y",0,IF(ISERROR(VLOOKUP(B8,MASData,4,FALSE)),0,VLOOKUP(B8,MASData,4,FALSE))) -> 0 | H8: =IF($C$4=0,"N",'V9 Calculator'!F19) -> N | I8: Health
B9: =IF(H9="Y","Monitor - Dev ","Monitor - Not Selected ") -> Monitor - Not Selected | C9: =IF(ISERROR(VLOOKUP(B9,MASData,2,FALSE)),0,VLOOKUP(B9,MASData,2,FALSE)) -> 0 | D9: =IF(ISERROR(VLOOKUP(B9,MASData,3,FALSE)),0,VLOOKUP(B9,MASData,3,FALSE)) -> 0 | E9: =IF(ISERROR(VLOOKUP(B9,MASData,4,FALSE)),0,VLOOKUP(B9,MASData,4,FALSE)) -> 0 | H9: =IF($C$4=0,"N",'V9 Calculator'!F20) -> N | I9: Monitor
B10: =IF(H10="Y","Predict - Dev ","Predict - Not Selected ") -> Predict - Not Selected | C10: =IF(ISERROR(VLOOKUP(B10,MASData,2,FALSE)),0,VLOOKUP(B10,MASData,2,FALSE)) -> 0 | D10: =IF(ISERROR(VLOOKUP(B10,MASData,3,FALSE)),0,VLOOKUP(B10,MASData,3,FALSE)) -> 0 | E10: =IF(ISERROR(VLOOKUP(B10,MASData,4,FALSE)),0,VLOOKUP(B10,MASData,4,FALSE)) -> 0 | H10: =IF($C$4=0,"N",'V9 Calculator'!F21) -> N | I10: Predict
B11: =IF(H11="Y","Maximo IT - Dev ","Maximo IT - Not Selected ") -> Maximo IT - Not Selected | C11: =IF(AND(H7="N",H8="N",H11="Y"),IF(ISERROR(VLOOKUP(B11,MASData,2,FALSE)),0,VLOOKUP(B11,MASData,2,FALSE)),0) -> 0 | D11: =IF(AND(H7="N",H8="N",H11="Y"),IF(ISERROR(VLOOKUP(B11,MASData,3,FALSE)),0,VLOOKUP(B11,MASData,3,FALSE)),0) -> 0 | E11: =IF(AND(H7="N",H8="N",H11="Y"),IF(ISERROR(VLOOKUP(B11,MASData,4,FALSE)),0,VLOOKUP(B11,MASData,4,FALSE)),0) -> 0 | H11: =IF($C$4=0,"N",'V9 Calculator'!F22) -> N | I11: Maximo IT
B12: =IF(H12="Y","Visual Inspection - Dev ","Visual Inspection - Not Selected ") -> Visual Inspection - Dev | C12: =IF(ISERROR(VLOOKUP(B12,MASData,2,FALSE)),0,VLOOKUP(B12,MASData,2,FALSE)) -> 4 | D12: =IF(ISERROR(VLOOKUP(B12,MASData,3,FALSE)),0,VLOOKUP(B12,MASData,3,FALSE)) -> 64 | E12: =IF(ISERROR(VLOOKUP(B12,MASData,4,FALSE)),0,VLOOKUP(B12,MASData,4,FALSE)) -> 115 | F12: =IF(ISERROR(VLOOKUP(B12,MASData,6,FALSE)),0,VLOOKUP(B12,MASData,6,FALSE)) -> 1 | H12: =IF($C$4=0,"N",'V9 Calculator'!F23) -> Y | I12: Visual Inspection
B13: =IF(H13="Y","Assist - Dev ","Assist - Not Selected ") -> Assist - Not Selected | C13: =IF(ISERROR(VLOOKUP(B13,MASData,2,FALSE)),0,VLOOKUP(B13,MASData,2,FALSE)) -> 0 | D13: =IF(ISERROR(VLOOKUP(B13,MASData,3,FALSE)),0,VLOOKUP(B13,MASData,3,FALSE)) -> 0 | E13: =IF(ISERROR(VLOOKUP(B13,MASData,4,FALSE)),0,VLOOKUP(B13,MASData,4,FALSE)) -> 0 | H13: =IF($C$4=0,"N",'V9 Calculator'!F24) -> N | I13: Assist
B14: =IF(H14="Y","Optimizer - Dev ","Optimizer - Not Selected ") -> Optimizer - Not Selected | C14: =IF(ISERROR(VLOOKUP(B14,MASData,2,FALSE)),0,VLOOKUP(B14,MASData,2,FALSE)) -> 0 | D14: =IF(ISERROR(VLOOKUP(B14,MASData,3,FALSE)),0,VLOOKUP(B14,MASData,3,FALSE)) -> 0 | E14: =IF(ISERROR(VLOOKUP(B14,MASData,4,FALSE)),0,VLOOKUP(B14,MASData,4,FALSE)) -> 0 | H14: =IF($C$4=0,"N",'V9 Calculator'!F25) -> N | I14: Optimizer
B15: Total Application Quantities: | C15: =SUM(C7:C14) -> 6 | D15: =SUM(D7:D14) -> 82 | E15: =SUM(E7:E14) -> 115 | F15: =SUM(F7:F14) -> 1
B17: Additional Application Sizing | C17: vCPU | D17: Memory (GiB) | E17: File Storage (GiB) | F17: DB2 Storage (GiB)
B18: =IF(OR(H7="Y",H8="Y",H11="Y"),"Manage/Health/IT DB2 - Dev ","Manage/Health/IT DB2 - Not Selected ") -> Manage/Health/IT DB2 - Dev | C18: =IF('V9 Calculator'!F7="Y",0,IF(ISERROR(VLOOKUP(B18,MASData,2,FALSE)),0,VLOOKUP(B18,MASData,2,FALSE))) -> 6 | D18: =IF('V9 Calculator'!F7="Y",0,IF(ISERROR(VLOOKUP(B18,MASData,3,FALSE)),0,VLOOKUP(B18,MASData,3,FALSE))) -> 24 | E18: =IF('V9 Calculator'!F7="Y",0,IF(ISERROR(VLOOKUP(B18,MASData,4,FALSE)),0,VLOOKUP(B18,MASData,4,FALSE))) -> 0 | F18: =IF(OR('V9 Calculator'!F7="Y",$C$4=0),0,IF('V9 Calculator'!F13="N",IF(ISERROR(VLOOKUP(B18,MASData,5,FALSE)),0,VLOOKUP(B18,MASData,5,FALSE)),'V9 Calculator'!P29)) -> 256
B19: =IF(H9="Y","Monitor DB2 - Dev ","Monitor DB2 - Not Selected ") -> Monitor DB2 - Not Selected | C19: =IF('V9 Calculator'!F8="Y",0,IF(ISERROR(VLOOKUP(B19,MASData,2,FALSE)),0,VLOOKUP(B19,MASData,2,FALSE))) -> 0 | D19: =IF('V9 Calculator'!F8="Y",0,IF(ISERROR(VLOOKUP(B19,MASData,3,FALSE)),0,VLOOKUP(B19,MASData,3,FALSE))) -> 0 | E19: =IF('V9 Calculator'!F8="Y",0,IF(ISERROR(VLOOKUP(B19,MASData,4,FALSE)),0,VLOOKUP(B19,MASData,4,FALSE))) -> 0 | F19: =IF(OR('V9 Calculator'!F8="Y",$C$4=0),0,IF('V9 Calculator'!F13="N",IF(ISERROR(VLOOKUP(B19,MASData,5,FALSE)),0,VLOOKUP(B19,MASData,5,FALSE)),'V9 Calculator'!P30)) -> 0
B20: =IF(H7="Y","Manage - (MIF, Rprt, Crontask) + Cognos ","Manage - Not Selected ") -> Manage - (MIF, Rprt, Crontask) + Cognos | C20: =IF(ISERROR(VLOOKUP(B20,MASData,2,FALSE)),0,VLOOKUP(B20,MASData,2,FALSE))+IF(OR($C$4=0,H7="N"),0,IF(ISERROR(VLOOKUP("Cognos",MASData,2,FALSE)),0,VLOOKUP("Cognos",MASData,2,FALSE))) -> 0 | D20: =IF(ISERROR(VLOOKUP(B20,MASData,3,FALSE)),0,VLOOKUP(B20,MASData,3,FALSE))+IF(OR($C$4=0,H7="N"),0,IF(ISERROR(VLOOKUP("Cognos",MASData,3,FALSE)),0,VLOOKUP("Cognos",MASData,3,FALSE))) -> 0 | E20: =IF(ISERROR(VLOOKUP(B20,MASData,4,FALSE)),0,VLOOKUP(B20,MASData,4,FALSE))+IF(OR($C$4=0,H7="N"),0,IF(ISERROR(VLOOKUP("Cognos",MASData,4,FALSE)),0,VLOOKUP("Cognos",MASData,4,FALSE))) -> 0 | F20: =IF(ISERROR(VLOOKUP(B20,MASData,5,FALSE)),0,VLOOKUP(B20,MASData,5,FALSE))+IF(OR($C$4=0,H7="N"),0,IF(ISERROR(VLOOKUP("Cognos",MASData,5,FALSE)),0,VLOOKUP("Cognos",MASData,5,FALSE))) -> 0
B21: =IF(H7="Y","Manage - Industry Solutions ","Manage - Not Selected ") -> Manage - Industry Solutions | C21: =IF(AND(H7="Y",OR(H21="Y",I21="Y",J21="Y",K21="Y")),IF(ISERROR(VLOOKUP(B21,MASData,2,FALSE)),0,VLOOKUP(B21,MASData,2,FALSE)),0) -> 0 | D21: =IF(AND(H7="Y",OR(H21="Y",I21="Y",J21="Y",K21="Y")),IF(ISERROR(VLOOKUP(B21,MASData,3,FALSE)),0,VLOOKUP(B21,MASData,3,FALSE)),0) -> 0 | E21: =IF(AND(H7="Y",OR(H21="Y",I21="Y",J21="Y",K21="Y")),IF(ISERROR(VLOOKUP(B21,MASData,4,FALSE)),0,VLOOKUP(B21,MASData,4,FALSE)),0) -> 0 | F21: =IF(AND(H7="Y",OR(H21="Y",I21="Y",J21="Y",K21="Y")),IF(ISERROR(VLOOKUP(B21,MASData,5,FALSE)),0,VLOOKUP(B21,MASData,5,FALSE)),0) -> 0 | H21: =IF('V9 Calculator'!G35="Y","Y","N") -> N | I21: =IF('V9 Calculator'!H35="Y","Y","N") -> N | J21: =IF('V9 Calculator'!I35="Y","Y","N") -> N | K21: =IF('V9 Calculator'!J34="Y","Y","N") -> N
B22: =IF(H10="Y","Watson Studio - Dev ","Watson Studio - Not Selected ") -> Watson Studio - Not Selected | C22: =IF(ISERROR(VLOOKUP(B22,MASData,2,FALSE)),0,VLOOKUP(B22,MASData,2,FALSE)) -> 0 | D22: =IF(ISERROR(VLOOKUP(B22,MASData,3,FALSE)),0,VLOOKUP(B22,MASData,3,FALSE)) -> 0 | E22: =IF(ISERROR(VLOOKUP(B22,MASData,4,FALSE)),0,VLOOKUP(B22,MASData,4,FALSE)) -> 0 | F22: =IF(ISERROR(VLOOKUP(B22,MASData,5,FALSE)),0,VLOOKUP(B22,MASData,5,FALSE)) -> 0
B23: =IF(H10="Y","Watson ML - Dev ","Watson ML - Not Selected ") -> Watson ML - Not Selected | C23: =IF(ISERROR(VLOOKUP(B23,MASData,2,FALSE)),0,VLOOKUP(B23,MASData,2,FALSE)) -> 0 | D23: =IF(ISERROR(VLOOKUP(B23,MASData,3,FALSE)),0,VLOOKUP(B23,MASData,3,FALSE)) -> 0 | E23: =IF(ISERROR(VLOOKUP(B23,MASData,4,FALSE)),0,VLOOKUP(B23,MASData,4,FALSE)) -> 0 | F23: =IF(ISERROR(VLOOKUP(B23,MASData,5,FALSE)),0,VLOOKUP(B23,MASData,5,FALSE)) -> 0
B24: =IF(H9="Y","Kafka - Dev ","Kafka - Not Selected ") -> Kafka - Not Selected | C24: =IF(ISERROR(VLOOKUP(B24,MASData,2,FALSE)),0,VLOOKUP(B24,MASData,2,FALSE)) -> 0 | D24: =IF(ISERROR(VLOOKUP(B24,MASData,3,FALSE)),0,VLOOKUP(B24,MASData,3,FALSE)) -> 0 | E24: =IF(ISERROR(VLOOKUP(B24,MASData,4,FALSE)),0,VLOOKUP(B24,MASData,4,FALSE)) -> 0 | F24: =IF(ISERROR(VLOOKUP(B24,MASData,5,FALSE)),0,VLOOKUP(B24,MASData,5,FALSE)) -> 0
B25: =IF(H13="Y","CouchDB - Dev ","CouchDB - Not Selected ") -> CouchDB - Not Selected | C25: =IF(ISERROR(VLOOKUP(B25,MASData,2,FALSE)),0,VLOOKUP(B25,MASData,2,FALSE)) -> 0 | D25: =IF(ISERROR(VLOOKUP(B25,MASData,3,FALSE)),0,VLOOKUP(B25,MASData,3,FALSE)) -> 0 | E25: =IF(ISERROR(VLOOKUP(B25,MASData,4,FALSE)),0,VLOOKUP(B25,MASData,4,FALSE)) -> 0 | F25: =IF(ISERROR(VLOOKUP(B25,MASData,5,FALSE)),0,VLOOKUP(B25,MASData,5,FALSE)) -> 0
B26: =IF(AND(COUNTIF(H7:H14,"Y")>0,$C$4>0),"MongoDB - Dev ","MongoDB - Not Required") -> MongoDB - Dev | C26: =IF(ISERROR(VLOOKUP(B26,MASData,2,FALSE)),0,VLOOKUP(B26,MASData,2,FALSE)) -> 1.5 | D26: =IF(ISERROR(VLOOKUP(B26,MASData,3,FALSE)),0,VLOOKUP(B26,MASData,3,FALSE)) -> 3 | E26: =IF(ISERROR(VLOOKUP(B26,MASData,4,FALSE)),0,VLOOKUP(B26,MASData,4,FALSE)) -> 20 | F26: =IF(ISERROR(VLOOKUP(B26,MASData,5,FALSE)),0,VLOOKUP(B26,MASData,5,FALSE)) -> 0
B27: Total Additional Application Quantities: | C27: =SUM(C18:C26) -> 7.5 | D27: =SUM(D18:D26) -> 27 | E27: =SUM(E18:E26) -> 20 | F27: =SUM(F18:F26) -> 256
B29: Cluster Wide Allocations | C29: vCPU | D29: Memory (GiB) | E29: File Storage (GiB) | F29: DB2 Storage (GiB)
B30: =IF(C4=0,"MAS Core - Not Selected",'V9 Calculator'!L41) -> MAS Core | C30: =IF(ISERROR(VLOOKUP(B30,MASData,2,FALSE)),0,VLOOKUP(B30,MASData,2,FALSE)) -> 2 | D30: =IF(ISERROR(VLOOKUP(B30,MASData,3,FALSE)),0,VLOOKUP(B30,MASData,3,FALSE)) -> 2 | E30: =IF(ISERROR(VLOOKUP(B30,MASData,4,FALSE)),0,VLOOKUP(B30,MASData,4,FALSE)) -> 20 | F30: =IF(ISERROR(VLOOKUP(B30,MASData,5,FALSE)),0,VLOOKUP(B30,MASData,5,FALSE)) -> 0
B31: =IF(C4=0,"OpenShift Worker Nodes - Not Selected",'V9 Calculator'!L42) -> OpenShift Worker Nodes - Xsmall/Min | C31: =IF(ISERROR(VLOOKUP(B31,MASData,2,FALSE)),0,VLOOKUP(B31,MASData,2,FALSE)) -> 4 | D31: =IF(ISERROR(VLOOKUP(B31,MASData,3,FALSE)),0,VLOOKUP(B31,MASData,3,FALSE)) -> 16 | E31: =IF(ISERROR(VLOOKUP(B31,MASData,4,FALSE)),0,VLOOKUP(B31,MASData,4,FALSE)) -> 240 | F31: =IF(ISERROR(VLOOKUP(B31,MASData,5,FALSE)),0,VLOOKUP(B31,MASData,5,FALSE)) -> 0
B32: =IF(C4=0,"CP4D Base - Not Selected",'V9 Calculator'!L43) -> CP4D Base | C32: =IF(OR($H$7="Y",$H$8="Y",$H$9="Y",$H$10="Y",$H$11="Y",$H$13="Y"),IF(ISERROR(VLOOKUP(B32,MASData,2,FALSE)),0,VLOOKUP(B32,MASData,2,FALSE)),0) -> 14 | D32: =IF(OR($H$7="Y",$H$8="Y",$H$9="Y",$H$10="Y",$H$11="Y",$B$13="Y"),IF(ISERROR(VLOOKUP(B32,MASData,3,FALSE)),0,VLOOKUP(B32,MASData,3,FALSE)),0) -> 10 | E32: =IF(OR($H$7="Y",$H$8="Y",$H$9="Y",$H$10="Y",$H$11="Y",$B$13="Y"),IF(ISERROR(VLOOKUP(B32,MASData,4,FALSE)),0,VLOOKUP(B32,MASData,4,FALSE)),0) -> 655 | F32: =IF(OR($H$7="Y",$H$8="Y",$H$9="Y",$H$10="Y",$H$11="Y",$B$13="Y"),IF(ISERROR(VLOOKUP(B32,MASData,5,FALSE)),0,VLOOKUP(B32,MASData,5,FALSE)),0) -> 0
B33: Total Cluster Wide Quantities: | C33: =SUM(C30:C32) -> 20 | D33: =SUM(D30:D32) -> 28 | E33: =SUM(E30:E32) -> 915 | F33: =SUM(F30:F32) -> 0
B35: TOTALS per Dev Cluster | C35: vCPU | D35: Memory (GiB) | E35: File Storage (GiB) | F35: DB2 Storage (GiB) | G35: GPU
B36: One Dev Cluster Requirements | C36: =C33+C27+C15 -> 33.5 | D36: =D33+D27+D15 -> 137 | E36: =E33+E27+E15 -> 1050 | F36: =F33+F27 -> 256 | G36: =F15 -> 1
B38: ="Total Dev Cluster Requirements * "&C4 -> Total Dev Cluster Requirements * 1 | C38: =C36*$C$4 -> 33.5 | D38: =D36*$C$4 -> 137 | E38: =E36*$C$4 -> 1050 | F38: =F36*$C$4 -> 256 | G38: =G36*$C$4 -> 1

Sheet Predict Data Points
C1: Predict Data Point Calculator | M1: Predict Data Point Calculator
C3: Data Point Calculation | K3: 20 | M3: Data Point Calculation
C4: Number of Groups | D4: 2 | K4: 5 | M4: Number of Groups | N4: 5 | O4: matters for trainingin only
C5: # of Models per Group | D5: 1 | F5: 50 models | K5: 750 | M5: # of Models per Group | N5: 25
C6: # of Assets per Group | D6: 40 | F6: 2000 assets | G6: at most from Monitor | I6: Rows per minute | K6: 50 | M6: # of Assets per Group | N6: 60 | O6: This is found in Monitor
C7: Average # of Sensors per Asset | D7: 15 | F7: each row is an asset | G7: ='V9 Calculator'!J19 -> 0 | I7: =G7/D7*D5 -> 0 | K7: 24 | M7: Average # of Sensors per Asset | N7: 10 | O7: 60,000 sensors driving data
C8: Frequency of data collection | D8: 24 | E8: Times per day | F8: =D8*D6*D4 -> 1920 | G8: =D4*D6*D7 -> 1200 | K8: 1 | M8: Frequency of data collection | N8: 24 | O8: Times per day
C9: Frequency of Scoring | D9: 1 | E9: Times per day | M9: Frequency of Scoring | N9: 1 | O9: Times per day
F10: =50*F8 -> 96000
G11: 24 lines | H11: 60,000 sensors
C12: Training | M12: Training
C13: Records per Day | D13: 2 | E13: Number of lines of data | K13: 1 | M13: Records per Day | N13: 1 | O13: Number of lines of data
C14: # of sensors per asset average | D14: =D7 -> 15 | M14: # of sensors per asset average | N14: =N7 -> 10
C15: # of assets | D15: =D6*D4 -> 80 | M15: # of assets | N15: =N6*N4 -> 300
C16: Daily Pre-Aggregation? | D16: N | K16: N | M16: Daily Pre-Aggregation? | N16: N
C17: Years of Retention | D17: 3 | K17: 3 | M17: Years of Retention | N17: 3
F18: =30*48000*50 -> 72000000
C19: Results | M19: Results
C20: Scoring Load | D20: =D4*D5*D6*D7*(D8)*D9 -> 28800 | E20: Scoring Total per day across all sensors | G20: =D20/1440 -> 20 | M20: Scoring Load | N20: =N4*N5*N6*N7*(N8)*N9 -> 1800000 | O20: Scoring Total per day across all sensors
C21: Training Data Points | D21: =(D15*D17*365*D13*D14)/IF(D16="Y",24,1) -> 2628000 | E21: Data points over a 3 year period | I21: Models | J21: 25 | M21: Training Data Points | N21: =(N15*N17*365*N13*N14)/IF(N16="Y",24,1) -> 3285000 | O21: Data points over a 3 year period
I22: Asset Groups | J22: 5
B23: Y | C23: Training + Scoring Load | D23: =D20+D21 -> 2656800 | I23: Assets Per Group | J23: 60 | M23: Training + Scoring Load
B24: N | F24: each sensor is a line | I24: Sensors Per Asset | J24: 10

Sheet Data Source
A2: Existing DB2 Database Selection | B2: ='V9 Calculator'!F7 -> N
A3: Manage | B3: ='V9 Calculator'!F18 -> Y | C3: User Calculation | H3: JVM Calculation | Q3: Sizing and Quantity Definitions
A4: Health | B4: ='V9 Calculator'!F19 -> N | C4: JVMs | D4: vCPUs | E4: Memory | F4: File Storage | G4: DB Storage | H4: JVMs | I4: vCPUs | J4: Memory | K4: File Storage | L4: DB Storage | T4: Size Ranges - Up To:
A5: Users per JVM | B5: 50 | C5: =ROUNDUP(B18/B5,0) -> 0 | D5: Manage | H5: =B19 -> 2 | I5: Manage | P5: Active Sizes | R5: Metric | S5: Dev | T5: Xsmall/Min | U5: Small | V5: Medium | W5: Large | X5: Beyond Large
A6: vCPUs per JVM | B6: 1.5 | D6: =IF(B3="N",0,($C$5*$B$6)+$B$8) -> 0.5 | E6: =IF(B3="N",0,($C$5*$B$7)+$B$9) -> 1 | F6: 0 | G6: =IF(OR(B3="N",B2="Y"),0,$B$11*$C$5) -> 0 | I6: =IF(B3="N",0,($H$5*$B$6)+$B$8) -> 3.5 | J6: =IF(B3="N",0,($H$5*$B$7)+$B$9) -> 19 | K6: 0 | L6: =IF(OR(B3="N",B2="Y"),0,$H$5*$B$11) -> 298 | P6: =B24 -> Xsmall/Min | Q6: Manage | R6: Users | S6: 0 | T6: 50 | U6: 100 | V6: 250 | W6: 500 | X6: =W6+V6 -> 750
A7: Memory GiB per JVM | B7: 9 | C7: =IF(B3="Y",0,ROUNDUP(B21/B5,0)) -> 0 | D7: =IF(B3="Y","Health 0 (Manage Active)","Health Stand Alone") -> Health 0 (Manage Active) | I7: Health Stand Alone | P7: =IF('V9 Calculator'!F20="Y",IF(AND('V9 Calculator'!H20<=T7,'V9 Calculator'!J20<=T8),T5,IF(AND('V9 Calculator'!H20<=U7,'V9 Calculator'!J20<=U8),U5,IF(AND('V9 Calculator'!H20<=V7,'V9 Calculator'!J20<=V8),V5,IF(AND('V9 Calculator'!H20<=W7,'V9 Calculator'!J20<=W8),W5,X5)))),"Not Selected ") -> Not Selected | Q7: Monitor | R7: i/o points | S7: 0 | T7: 1000 | U7: 5000 | V7: 50000 | W7: 500000 | X7: =W7+V7 -> 550000
A8: vCPUs to Add to Final | B8: 0.5 | D8: =IF(OR(B3="Y",B4="N"),0,($C$7*$B$6)+$B$8) -> 0 | E8: =IF(OR(B3="Y",B4="N"),0,($C$7*$B$7)+$B$9) -> 0 | F8: 0 | G8: =IF(OR(B3="Y",B4="N",B2="Y"),0,$C$7*$B$11) -> 0 | I8: =IF(OR(B3="Y",B4="N"),0,($H$5*$B$6)+$B$8) -> 0 | J8: =IF(OR(B3="Y",B4="N"),0,($H$5*$B$7)+$B$9) -> 0 | K8: 0 | L8: =IF(OR(B3="Y",B4="N",B2="Y"),0,$H$5*$B$11) -> 0 | R8: Users | S8: 0 | T8: 1 | U8: 10 | V8: 40 | W8: 60 | X8: =W8+V8 -> 100
A9: Memory to Add to Final | B9: 1 | P9: =B24 -> Xsmall/Min | Q9: Health | R9: Users | S9: 0 | T9: 1 | U9: 5 | V9: 15 | W9: 35 | X9: =W9+V9 -> 50
A10: DB2 Storage - Per Manage User | B10: =N35 -> 2.98 | C10: =K12 -> 0 | D10: Maximo IT Stand Alone | H10: Maximo IT - Additional Users Entered: | K10: =IF(AND($B$3="Y",'V9 Calculator'!F22="Y"),'V9 Calculator'!J22,0) -> 0 | R10: Assets | S10: 0 | T10: 500 | U10: 3000 | V10: 20000 | W10: 50000 | X10: =W10+V10 -> 70000
A11: DB2 Storage - Per JVM | B11: =B5*B10 -> 149 | C11: =ROUNDUP(K11/B5,0) -> 0 | D11: =IF(OR(K13="N",B3="Y"),0,(MAX(C10,C11)*B6)+B8) -> 0 | E11: =IF(OR(K13="N",B3="Y"),0,(MAX(C10,C11)*B7)+B9) -> 0 | F11: 0 | G11: =IF(OR(K13="N",B3="Y",B2="Y"),0,MAX(C10,C11)*B11) -> 0 | H11: Maximo IT - StandAlone Users Entered: | K11: =IF(AND($B$3="N",'V9 Calculator'!F22="Y"),'V9 Calculator'!J22,0) -> 0 | P11: =IF('V9 Calculator'!F21="Y",IF('V9 Calculator'!H21<=T12,T5,IF('V9 Calculator'!H21<=U12,U5,IF('V9 Calculator'!H21<=V12,V5,IF('V9 Calculator'!H21<=W12,W5,X5)))),"Not Selected ") -> Not Selected | Q11: Predict | R11: Scoring Load- Scoring | S11: 0 | T11: 100 | U11: 12500 | V11: 85000 | W11: 210000 | X11: =W11+V11 -> 295000
A12: DB2 Storage - Per Health User | B12: =N41 -> 119.68 | C12: =ROUNDUP(K10/B5,0) -> 0 | D12: Maximo IT Additional Requirements to Manage | H12: Maximo IT - StandAlone JVMs Entered: | K12: =IF(AND($B$3="N",'V9 Calculator'!F22="Y"),'V9 Calculator'!H22,0) -> 0 | R12: Data Points - Training | S12: 0 | T12: =U12/20 -> 164250 | U12: =V12/20 -> 3285000 | V12: 65700000 | W12: 821500000 | X12: =W12+V12 -> 887200000
A13: DB2 Storage - Per Asset | B13: =P41 -> 0.17 | D13: =IF(K13="N",0,ROUND(C12*B6,1)) -> 0 | E13: =IF(K13="N",0,ROUND(C12*B7,1)) -> 0 | F13: 0 | G13: =IF(B2="Y",0,B11*C12) -> 0 | J13: Maximo IT | K13: ='V9 Calculator'!F22 -> N | R13: Users | S13: 0 | T13: 1 | U13: 2 | V13: 10 | W13: 35 | X13: =W13+V13 -> 45
A14: Manage IntRptCrontask JVMs | C14: =SUM(B15:B17) -> 0 | D14: Manage Integrations, Reporting, Crontask JVMs | I14: Manage Industry Solutions Calculations | P14: =IF('V9 Calculator'!F23="Y",IF('V9 Calculator'!H23<=T14,T5,IF('V9 Calculator'!H23<=U14,U5,IF('V9 Calculator'!H23<=V14,V5,IF('V9 Calculator'!H23<=W14,W5,X5)))),"Not Selected ") -> Xsmall/Min | Q14: Visual Inspection | R14: Users | S14: 0 | T14: 1 | U14: 4 | V14: 8 | W14: 16 | X14: =W14+V14 -> 24
A15: Integrations | B15: ='V9 Calculator'!H32 -> 0 | D15: =ROUNDUP(B6*C14,0) -> 0 | E15: =B7*C14 -> 0 | F15: 0 | G15: 0 | I15: Aviation | J15: PlaceHold 2 | K15: PlaceHold 3 | L15: Totals | M15: Totals | P15: =IF('V9 Calculator'!F24="Y",IF('V9 Calculator'!H24<=T15,T5,IF('V9 Calculator'!H24<=U15,U5,IF('V9 Calculator'!H24<=V15,V5,IF('V9 Calculator'!H24<=W15,W5,X5)))),"Not Selected ") -> Not Selected | Q15: Assist | R15: Users | S15: 0 | T15: 2 | U15: 3 | V15: 10 | W15: 30 | X15: =W15+V15 -> 40
A16: Reporting | B16: ='V9 Calculator'!I32 -> 0 | H16: vCPUs==> | I16: =IF('V9 Calculator'!G35="Y",1.5,0) -> 0 | J16: =IF('V9 Calculator'!H34="Y",1.5,0) -> 0 | K16: =IF('V9 Calculator'!I35="Y",1.5,0) -> 0 | M16: =SUM(I16:K16) -> 0 | R16: Documents | S16: 0 | T16: 50000 | U16: 100000 | V16: 600000 | W16: 1000000 | X16: =W16+V16 -> 1600000
A17: Crontask Usage | B17: ='V9 Calculator'!J32 -> 0 | H17: Mem==> | I17: =IF('V9 Calculator'!G35="Y",9,0) -> 0 | J17: =IF('V9 Calculator'!H34="Y",9,0) -> 0 | K17: =IF('V9 Calculator'!I35="Y",9,0) -> 0 | M17: =SUM(I17:K17) -> 0 | Q17: Safety | R17: Workers Monitored | S17: 0 | T17: 50 | U17: 250 | V17: 2500 | W17: 10000 | X17: =W17+V17 -> 12500
A18: Manage Users Entered | B18: =IF(B3="N",0,'V9 Calculator'!J18) -> 0 | R18: i/o points | S18: 0 | T18: 1000 | U18: 5000 | V18: 50000 | W18: 200000 | X18: =W18+V18 -> 250000
A19: Manage/Health JVMs Entered | B19: =IF(B3="N",0,'V9 Calculator'!H18) -> 2 | P19: =IF('V9 Calculator'!F22="Y",IF('V9 Calculator'!H22<=T20,T5,IF('V9 Calculator'!H22<=U20,U5,IF('V9 Calculator'!H22<=V20,V5,IF('V9 Calculator'!H22<=W20,W5,X5)))),"Not Selected ") -> Not Selected | Q19: H & P - Utilities | R19: Users | S19: n/a | T19: n/a | U19: n/a | V19: n/a | W19: n/a | X19: n/a
A20: Health Users Entered | B20: =IF(B4="N",0,'V9 Calculator'!J19) -> 0 | R20: Asset Classes | S20: 0 | T20: 5 | U20: 10 | V20: 30 | W20: 50 | X20: 80
A21: Health Equivelant Manage Users | B21: =B20*L45 -> 0 | P21: =IF('V9 Calculator'!F22="Y",IF('V9 Calculator'!H22<=T21,T5,IF('V9 Calculator'!H22<=U21,U5,IF('V9 Calculator'!H22<=V21,V5,IF('V9 Calculator'!H22<=W21,W5,X5)))),"Not Selected ") -> Not Selected | Q21: Maximo IT | R21: Users | S21: 0 | T21: 100 | U21: 200 | V21: 500 | W21: 750 | X21: =W21+V21 -> 1250
A22: Health Assets Entered | P22: =IF('V9 Calculator'!F25="Y",IF('V9 Calculator'!H25<=T22,T5,IF('V9 Calculator'!H25<=U22,U5,IF('V9 Calculator'!H25<=V22,V5,IF('V9 Calculator'!H25<=W22,W5,X5)))),"Not Selected ") -> Not Selected | Q22: Optimizer | R22: Users | S22: 0 | T22: 50 | U22: 100 | V22: 250 | W22: 500 | X22: =W22+V22 -> 750
A23: Max JVMs Between Manage/Health/IT | B23: =MAX($C$5,$H$5,$C$7,$C$10,$C$11,$C$12) -> 2 | O23: =2800/33 -> 84.848485 | T23: 1 | U23: 2 | V23: 3 | W23: 4 | X23: 5
A24: DB2 Size for vCPUs & Memory | B24: =IF(AND($B$3="N",$B$4="N",$K$13="N"),"Not Selected ",IF($B$23<=2,"Xsmall/Min ",IF($B$23<=4,"Small ",IF($B$23<=10,"Medium ",IF($B$23<=15,"Large ","Beyond Large "))))) -> Xsmall/Min
A25: Total Master Node Requirements | B25: ='V9 Calculator'!F5 -> Y | C25: Node Count | D25: vCPU | E25: Memory | F25: Storage
B26: ='V9 Calculator'!F6 -> N | C26: =IF(B26="Y",0,IF(B25="N",1,3)) -> 3 | D26: =C26*B138 -> 12 | E26: =C26*C138 -> 48 | F26: =C26*D138 -> 360
A28: Name | B28: vCPU | C28: Memory (GiB) | D28: File Storage (GiB) | E28: DB Storage (GiB) | F28: GPUs | G28: Rules / Include | J28: Mange / Health DB2 T-Shirt Calculations | Q28: Overall Size for Master OCP Nodes & Cluster Wide Applications | T28: Develoment Environments Calculation
A29: =$Q$6&" - "&$S$5 -> Manage - Dev | B29: 2 | C29: 18 | D29: 0 | E29: 256 | G29: Cp4d | J29: Name | L29: DB Storage | M29: Users | N29: Per User | O29: Assets | P29: Per Asset | Q29: Dev | R29: 0 | S29: Dev | T29: ='V9 Calculator'!F12*0.5 -> 0.5
A30: =$Q$6&" - Calculated " -> Manage - Calculated | B30: =MAX(D6,I6) -> 3.5 | C30: =MAX(E6,J6) -> 19 | D30: =MAX(F6,K6) -> 0 | E30: =MAX($G$6,$L$6) -> 298 | G30: Db2 | J30: =$Q$6&$T$5 -> ManageXsmall/Min | L30: 256 | M30: 100 | N30: =ROUND(L30/M30,2) -> 2.56 | Q30: Xsmall/Min | R30: 1 | S30: Xsmall/Min
A31: =$Q$9&" - "&$S$5 -> Health - Dev | B31: 2 | C31: 10 | D31: 0 | E31: 256 | G31: MongoDB | J31: =$Q$6&$U$5 -> ManageSmall | L31: 512 | M31: 200 | N31: =ROUND(L31/M31,2) -> 2.56 | Q31: Small | R31: 2 | S31: Small
A32: =$Q$9&" - Calculated " -> Health - Calculated | B32: =MAX(D8,I8) -> 0 | C32: =MAX(E8,J8) -> 0 | D32: =MAX(F8,K8) -> 0 | E32: =MAX(G8,L8) -> 0 | G32: IntRptCrontask | J32: =$Q$6&$V$5 -> ManageMedium | L32: 1200 | M32: 500 | N32: =ROUND(L32/M32,2) -> 2.4 | Q32: Medium | R32: 3 | S32: Medium
A33: =$Q$7&" - "&$S$5 -> Monitor - Dev | B33: 10 | C33: 33 | G33: Cp4d | J33: =$Q$6&$W$5 -> ManageLarge | L33: 2800 | M33: 751 | N33: =ROUND(L33/M33,2) -> 3.73 | Q33: Large | R33: 4 | S33: Large
A34: =$Q$7&" - "&$T$5 -> Monitor - Xsmall/Min | B34: 17 | C34: 33 | G34: Db2 | J34: =$Q$6&$X$5 -> ManageBeyond Large | L34: =L32+L33 -> 4000 | M34: 1100 | N34: =ROUND(L34/M34,2) -> 3.64 | Q34: Beyond Large | R34: 5 | S34: Beyond Large | T34: OCP Master Node Value
A35: =$Q$7&" - "&$U$5 -> Monitor - Small | B35: 17 | C35: 72 | G35: MongoDB | J35: Manage Average: | N35: =ROUND(AVERAGE(N30:N34),2) -> 2.98 | Q35: =IF(ISERROR(VLOOKUP(B24,Q29:R34,2,FALSE)),"",VLOOKUP(B24,Q29:R34,2,FALSE)) -> 1 | R35: =IF(MAX(Q35:Q42)=0,-1,MAX(Q35:Q42)) -> 1 | S35: =IF(ISERROR(VLOOKUP($R$35,$R$29:$S$34,2,FALSE)),"Not Selected ",VLOOKUP($R$35,$R$29:$S$34,2,FALSE)) -> Xsmall/Min | T35: =R35+T29 -> 1.5
A36: =$Q$7&" - "&$V$5 -> Monitor - Medium | B36: 28.5 | C36: 101 | G36: (IoT included) - Safety being removed, so no duplication possible | J36: =$Q$9&$T$5 -> HealthXsmall/Min | L36: 256 | M36: 1 | N36: =ROUND(L36/M36,2) -> 256 | O36: 500 | P36: =ROUND(L36/O36,2) -> 0.51 | Q36: =IF(ISERROR(VLOOKUP(P7,$Q$29:$R$34,2,FALSE)),"",VLOOKUP(P7,$Q$29:$R$34,2,FALSE))
A37: =$Q$7&" - "&$W$5 -> Monitor - Large | B37: 45 | C37: 150 | G37: Kafka | J37: =$Q$9&$U$5 -> HealthSmall | L37: 512 | M37: 5 | N37: =ROUND(L37/M37,2) -> 102.4 | O37: 3000 | P37: =ROUND(L37/O37,2) -> 0.17 | Q37: =IF(ISERROR(VLOOKUP(P9,$Q$29:$R$34,2,FALSE)),"",VLOOKUP(P9,$Q$29:$R$34,2,FALSE)) -> 1
A38: =$Q$7&" - "&$X$5 -> Monitor - Beyond Large | B38: =B36+B37 -> 73.5 | C38: =C36+C37 -> 251 | J38: =$Q$9&$V$5 -> HealthMedium | L38: 1200 | M38: 15 | N38: =ROUND(L38/M38,2) -> 80 | O38: 20000 | P38: =ROUND(L38/O38,2) -> 0.06 | Q38: =IF(ISERROR(VLOOKUP(P11,$Q$29:$R$34,2,FALSE)),"",VLOOKUP(P11,$Q$29:$R$34,2,FALSE))
A39: =$Q$11&" - "&$S$5 -> Predict - Dev | B39: 2 | C39: 0 | D39: 512 | E39: 0 | G39: Cp4d | J39: =$Q$9&$W$5 -> HealthLarge | L39: 2800 | M39: 35 | N39: =ROUND(L39/M39,2) -> 80 | O39: 50000 | P39: =ROUND(L39/O39,2) -> 0.06 | Q39: =IF(ISERROR(VLOOKUP(P14,$Q$29:$R$34,2,FALSE)),"",VLOOKUP(P14,$Q$29:$R$34,2,FALSE)) -> 1
A40: =$Q$11&" - "&$T$5 -> Predict - Xsmall/Min | B40: 2 | C40: 0 | D40: 512 | E40: 0 | G40: MongoDB | J40: =$Q$9&$X$5 -> HealthBeyond Large | L40: =L39+L38 -> 4000 | M40: 50 | N40: =ROUND(L40/M40,2) -> 80 | O40: =O39+O38 -> 70000 | P40: =ROUND(L40/O40,2) -> 0.06 | Q40: =IF(ISERROR(VLOOKUP(P15,$Q$29:$R$34,2,FALSE)),"",VLOOKUP(P15,$Q$29:$R$34,2,FALSE))
A41: =$Q$11&" - "&$U$5 -> Predict - Small | B41: 2 | C41: 0 | D41: 1024 | E41: 0 | G41: Watson Studio - Don't double count w/HPU | J41: Health Averages: | N41: =ROUND(AVERAGE(N36:N40),2) -> 119.68 | P41: =ROUND(AVERAGE(P36:P40),2) -> 0.17 | Q41: =IF(ISERROR(VLOOKUP(P19,$Q$29:$R$34,2,FALSE)),"",VLOOKUP(P19,$Q$29:$R$34,2,FALSE))
A42: =$Q$11&" - "&$V$5 -> Predict - Medium | B42: 2 | C42: 0 | D42: 2048 | E42: 0 | G42: Watson ML | Q42: =IF(ISERROR(VLOOKUP(P22,$Q$29:$R$34,2,FALSE)),"",VLOOKUP(P22,$Q$29:$R$34,2,FALSE))
...

Sheet Versions
B1: Version | C1: Updates
B2: v8_8 | C2: New Calculator - Major Update - Many Changes
C3: Modified Manage + Health to be formula driven
C4: Removed Safety
C5: Added Optimizer
C6: Revamped Development Environments - Cluster Wide
C7: Defined cluster wide allocations
C8: Added Option for Development DB Storage Size Selection - Equal Prod or Equal Calculated
C9: Added Option to Isolate DB Server - Default Config
C10: Manage + Health Updated to be a Single Allocation
C11: Separated File Storage from DB Storage Allocations
B13: v8_9 | C13: Added Manage Specific JVM Requirements when Manage is selected as "Y" - User input fields
C14: Updated the development environments to not count DB2 allocation if "use existing database" flag is set to "Y". This is set for both Manage and Monitor Database flags.
C15: Updated the alert flag for isolated DB2 server configuration to check when more servers are configured than database instances needed.
C16: Added OpenShift Master Node totals in the top level summary
C17: Updated the OpenShift Master Node summary totals in the System Configuration Results
B19: v8_10 | C19: Updated t-shirt size definitions for Monitor tied to I/O Points
C20: Added Cognos Configuration Option for Manage
C21: Fixed Development Calculations related to MongoDB
C22: Updated the Watson ML vCPU and Memory requirements based on updated data from Watson
B24: v9_0 | C24: Added Maximo IT - Part of Manage with Additional Users Optional by Selecting "Y"
C25: Added Maximo IT to both Production and Development Detail Sheets
C26: Removed H&P Utilities - Requirements collapsed into Health/Manage
C27: Removed Watson Discovery from Assist Requirements - Also removed CP4D requirement from Assist
C28: Updated OpenShift Worker Node Allocations based on overall size of the environment
C29: Updated Maximo Optimizer Data
C30: Increased MVI File System Space Requirements
C31: Updated OpenShift Master Node Allocations: xs, small, med = 4x16, large=8x32, beyond large=16x96 per node.
C32: Updated OpenShift Master Node Allocations to take into consideration Development Environments
C33: Fixed the Development Detail Page to Reflect Zero Allocations when Development Environments = 0
C34: Updated CP4D Allocations - Increased to 14 vCPUs, 10 GiB of Memory, 655 GiB of File Storage
C35: Added 20% increase of overall sizing if resilency/availability if selected
C36: Watson Studio & WatsonML vCPU and Memory allocations increased.
... C38: Added Ephemeral Storage (GiB) per Worker Node - This is system storage, not user/application storage (25GiB per vCPU)
B40: v9_0_1 | C40: Added option to remove CP4D allocation for all applications except Predict
C41: Added guidance on MIF, Reporting & Crontask
C42: Updated MongoDB for Large & Beyond Large - Reduced allocations significantly
C43: Fixed CP4D allocation when Maximo IT is selected with Use Existing Database flag set to "Y" (Set to allocations to 0)
C44: Fixed Watson Studio allocation in development environments when Maximo IT is the only application set to "Y"
C45: Fixed Maximo IT Development Environment allocations with Maximo IT is the only application set to "Y"
...
