Workbook
Name EnvironmentSizes: 'V9.1 Calculator'!$L$16:$L$23
Name MASData: #REF!

Sheet Guidance
B2: Notes on usage of the Maximo Real Estate and Facilities 9.1 Infrastructure Calculator
B4: 1 | C4: This needs to be used alongside the Maximo Application Suite Sizing Calculator (it will be merged in soon)
B5: 2 | C5: This tool is a blunt instrument for guidance only - please consider the following when inspecting the output
C6: a | D6: This should be completed by a Tech Seller engaging with the client to clarify requirements to input this spreadsheet (and interpret what they say)
C7: b | D7: At least one worker node needs to be greater than the biggest pod, preferably 2 for failover
C8: c | D8: In good deployments, the database is typically assigned its own worker node but this calculator does not do that, just gives you the minimum to run everything
C9: d | D9: Depending on the customer, the agent sizings may have to be different (some could be shrunk to 0.2 VPC and 2GB memory if they are not used)
C10: e | D10: Change the pod sizings (VPC, Memory and Storage) based on specific customer requirements and expected usage patterns
C11: f | D11: Each customer will have Worker Node size optimisations depending on their contracts with cloud providers or hardware providers
C12: g | D12: Change the worker node sizes on the v9.1 Calculator tab in the yellow boxes at the bottom to match their preferences
C13: h | D13: Do NOT change cell F16 (next to Environment Size) - it doesn't do anything
B14: 3 | C14: A development environment is assumed to be a small environment
B15: 4 | C15: Users are concurrent users using the system at the same time not registered users (concurrent here doesn't mean licensing type of concurrent vs authorised)
B16: 5 | C16: Size of environment is derived from concurrent users and number of active leases
B17: 6 | C17: Document manager storage is added to the database storage calculation - if you are using a CMIS ECM then leave Document Management Storage as 0
B18: 7 | C18: Master node calculations have been left in (for now) but use the ones from the Maximo Application Suite Sizing Calculator
B19: 8 | C19: All pre-requisite components for MAS for MREF will need to be calculated using the Maximo Application Suite Sizing Calculator
B20: 9 | C20: Can be used with an external (existing or new) database by setting cell F7 to Y
B21: 10 | C21: Check back often as this sizing calculaltor will be merged at some point with the Maximo Application Suite Infrastructure Calculator
C23: Feedback and comments to campbesc@us.ibm.com andy_barnes@uk.ibm.com

Sheet V9.1 Calculator
E2: IBM® Maximo Real Estate and Facilities Infrastructure Calculator - v11_5
E3: ***For GUIDANCE Purpose Only*** - Enter Inputs in Yellow Cells Only
C5: Enforce 3 Master + 2 Worker Nodes? | F5: N | G5: <-- Do not change | H5: 1Users: Users are defined as *concurrent* users when sizing the infrastructure requirements
C6: Installing into Existing OpenShift? | F6: N
C7: Install TRIRIGA w/Existing Database? | F7: N
C11: Number of Development Environments | F11: 4
C12: Enforce Dev DBStorage = Prod DBStorag? | F12: Y | L12: Production Cluster TOTALS | M12: vCPU | N12: Memory (GiB) | O12: File Storage (GiB) | P12: DB2 Storage (GiB)
M13: =M24+M28+M35 -> 31 | N13: =N24+N28+N35 -> 88 | O13: =O24+O28+O35 -> 80 | P13: =P28 -> 700
E14: Calculations | G14: Primary | I14: Secondary (Optional) | L14: OpenShift Master Node Requirements | M14: ='Load Calculation'!F55 -> 12 | N14: ='Load Calculation'!E55 -> 48 | O14: ='Load Calculation'!G55 -> 360 | P14: 0 | Q14: <- Do not use this line, use the one from the MAS spreadsheet
F15: Use (Y/N) | G15: Size Metric | H15: Quantity | I15: Size Metric | J15: Quantity | L15: Application Sizing | M15: vCPU | N15: Memory (GiB) | O15: File Storage (GiB)
B16: Selections | D16: Applications | E16: Environment Size | F16: Y | G16: Configure Users | H16: 11 | I16: Active Leases | J16: 1000 | L16: =E16&" - "&IF(F16="Y","Calculated ","Not Selected ") -> Environment Size - Calculated | M16: =OFFSET('Load Calculation'!J19,'Load Calculation'!E5,0) -> 31 | N16: =OFFSET('Load Calculation'!K19,'Load Calculation'!E5,0) -> 88 | O16: =OFFSET('Load Calculation'!N19,'Load Calculation'!E5,0) -> 80
B17: Y | G17: Base Users | H17: 60
B18: N | G18: Limited Users | H18: 50
G19: Self Service Users
B20: Isolate GPU? | G20: Doc Storage Size GB | H20: 200
B21: =IF(AND(COUNTIF(F16:F23,"Y")>1,F21="Y",F10="Y"),"Y","N") -> N
B23: CP4D Needed?
B24: =IF(OR(AND($F$16="Y",$F$7="N"),AND($F$17="Y",$F$7="N"),AND($F$18="Y",$F$8="N"),$F$19="Y",$F$20="Y",$F$22="Y"),"Y","N") -> Y | L24: Total Application Quantities: | M24: =SUM(M16:M23) -> 31 | N24: =SUM(N16:N23) -> 88 | O24: =SUM(O16:O23) -> 80 | P24: =SUM(P16:P23) -> 0
B26: Isolate DB? | L26: Additional Application Sizing | P26: Database Storage
B27: =IF(AND(OR(F7="N",F8="N"),F9="Y",COUNTIF(F16:F18,"Y")>0),"Y","N") -> N | L27: Real Estate and Facilities Database | P27: =OFFSET('Load Calculation'!O19,'Load Calculation'!E5,0) -> 700
P28: =SUM(P27:P27) -> 700
B29: Main Conf
B30: =IF(AND(B27="N",B21="N"),M46,IF(AND(B27="Y",B21="Y"),M46-M27-#REF!-M21-(F11*#REF!)-(F11*#REF!)-(F11*#REF!),IF(B21="Y",M46-M21-(F11*#REF!),M46-M27-#REF!-(F11*#REF!)-(F11*#REF!)))) -> 99
B31: =IF(AND(B27="N",B21="N"),N46,IF(AND(B27="Y",B21="Y"),N46-N27-#REF!-N21-(F11*#REF!)-(F11*#REF!)-(F11*#REF!),IF(B21="Y",N46-N21-(F11*#REF!),N46-N27-#REF!-(F11*#REF!)-(F11*#REF!)))) -> 304
B32: =IF(B21="N",Q53,Q53-P21-(F11*#REF!)) -> 0
B34: MVI Conf
B35: =IF(B21="N",0,M21+(F11*#REF!)) -> 0
B36: =IF(B21="N",0,N21+(F11*#REF!)) -> 0
B37: =IF(B21="N",0,Q53) -> 0 | L37: Production Cluster Configuration
L38: TOTALS | M38: vCPU | N38: Memory (GiB) | O38: File Storage (GiB) | P38: DB2 Storage (GiB)
B39: DB Conf | L39: Total Production Cluster Requirements | M39: =M24 -> 31 | N39: =N24 -> 88 | O39: =O24 -> 80 | P39: =P28+P35 -> 700
B40: =IF(B27="N",0,M27+#REF!+(F11*#REF!)+(F11*#REF!)) -> 0 | L40: Development Cluster(s) Configuration
B41: =IF(B27="N",0,N27+#REF!+(F11*#REF!)+(F11*#REF!)) -> 0 | L41: ="Total Development Clusters: " -> Total Development Clusters: | M41: =F11 -> 4
B42: =COUNTIF(M27:M27,">0")+COUNTIF(M27:M27,">0")*F11 -> 0 | L42: TOTALS | M42: vCPU | N42: Memory (GiB) | O42: File Storage (GiB) | P42: DB2 Storage (GiB)
L43: Total Dev Cluster(s) Requirements | M43: ='[1]Load Calculation'!J33*M41 -> 68 | N43: ='[1]Load Calculation'!K33*M41 -> 216 | O43: =IF('[1]V9.1 Calculator'!F12="Y",O39*M41,'[1]Load Calculation'!N33)*M41 -> 1280 | P43: ='[1]Load Calculation'!O33*M41 -> 880
B44: Beyond Large | L44: Production + Development Cluster Configuration
B45: =COUNTIF(L16:L34,"*Beyond Large*") -> 0 | L45: TOTALS | M45: vCPU | N45: Memory (GiB) | O45: File Storage (GiB) | P45: DB2 Storage (GiB)
M46: =M39+M43 -> 99 | N46: =N39+N43 -> 304 | O46: =O39+O43 -> 1360 | P46: =P39+P43 -> 1580
L48: System Configuration Results
L49: Each System Configuration | N49: System Quantity | O49: vCPU Factor | P49: Memory Factor
...

Sheet Load Calculation
E1: Calculated Environment Size | J1: user load | K1: leases
A2: User Load | C2: ='V9.1 Calculator'!H16+'V9.1 Calculator'!H17/3+'V9.1 Calculator'!H18/10+'V9.1 Calculator'!H19/100 -> 36 | E2: =IF($C$2<=$J$2,0,IF($C$2<=$J$3,1,IF($C$2<=$J$4,2,3))) -> 0 | I2: Small | J2: 250 | K2: 300
A3: Lease Load | C3: ='V9.1 Calculator'!J16 -> 1000 | E3: =IF($C$3<=$K$2,0,IF($C$3<=$K$3,1,IF($C$3<=$K$4,2,3))) -> 1 | I3: Medium | J3: 500 | K3: 3000
I4: Large | J4: 1500 | K4: 30000
A5: Overal Environment | E5: =MAX($E$2,$E$3) -> 1 | G5: =OFFSET($I$2,$E$5,0) -> Medium | I5: XL
I8: Additional storage contingency
I9: Small | J9: 10
I10: Medium | J10: 20
I11: Large | J11: 50
J16: Production | Q16: Test (assume small)
I18: Env | J18: VPC | K18: Memory | L18: Storage | M18: DB Storage | N18: File Storage | O18: Existing DB
I19: Small | J19: =SUM('MREF Pod Sizing'!D5:D9) -> 17 | K19: =SUM('MREF Pod Sizing'!E5:E9) -> 54 | L19: =IF('V9.1 Calculator'!F7="Y",SUM('MREF Pod Sizing'!F5:F7)+'V9.1 Calculator'!H20, SUM('MREF Pod Sizing'!F5:F9)+'V9.1 Calculator'!H20) -> 270 | M19: ='MREF Pod Sizing'!F8 +'V9.1 Calculator'!H20 -> 220 | N19: =L19-M19 -> 50 | O19: =IF('V9.1 Calculator'!F7="Y",0,'Load Calculation'!M19) -> 220
H20: =SUM(F17:F20) -> 0 | I20: Medium | J20: =SUM('MREF Pod Sizing'!D10:D17) -> 31 | K20: =SUM('MREF Pod Sizing'!E10:E17) -> 88 | L20: =IF('V9.1 Calculator'!F7="Y",SUM('MREF Pod Sizing'!F10:F15)+'V9.1 Calculator'!H20, SUM('MREF Pod Sizing'!F10:F17)+'V9.1 Calculator'!H20) -> 780 | M20: ='MREF Pod Sizing'!F16 +'V9.1 Calculator'!H20 -> 700 | N20: =L20-M20 -> 80 | O20: =IF('V9.1 Calculator'!F7="Y",0,'Load Calculation'!M20) -> 700
I21: Large | J21: =SUM('MREF Pod Sizing'!D18:D35) -> 81 | K21: =SUM('MREF Pod Sizing'!E18:E35) -> 228 | L21: =IF('V9.1 Calculator'!F7="Y",SUM('MREF Pod Sizing'!F18:F33)+'V9.1 Calculator'!H20, SUM('MREF Pod Sizing'!F18:F35)+'V9.1 Calculator'!H20) -> 2380 | M21: ='MREF Pod Sizing'!F34 +'V9.1 Calculator'!H20 -> 2200 | N21: =L21-M21 -> 180 | O21: =IF('V9.1 Calculator'!F7="Y",0,'Load Calculation'!M21) -> 2200
H30: =SUM(F26:F30) -> 0 | J30: Test (assume small in all cases)
A31: Moved to MREF Pod Sizing sheet
J32: VPC | K32: Memory | L32: Storage | M32: DB Storage | N32: File Storage | O32: Existing DB
J33: =J19 -> 17 | K33: =K19 -> 54 | L33: =L19 -> 270 | M33: =M19 -> 220 | N33: =N19 -> 50 | O33: =O19 -> 220
H44: =SUM(F36:F44) -> 0
A52: Master nodes x 3 | E52: 48 | F52: 12 | G52: 360
A55: Caculated Master Nodes | E55: =IF('V9.1 Calculator'!$F$6="Y"," ",$E$52) -> 48 | F55: =IF('V9.1 Calculator'!$F$6="Y"," ",$F$52) -> 12 | G55: =IF('V9.1 Calculator'!$F$6="Y"," ",$G$52) -> 360

Sheet MREF Pod Sizing
B2: Change this sheet to match the expected sizings for your particular client for the environment size you expect!
B4: Size | C4: Pod | D4: vpc | E4: memory | F4: storage
B5: Small | C5: UI App Server / Data Import Agent | D5: 2 | E5: 6 | F5: 10
B6: Small | C6: UI App Server / Data Import Agent | D6: 2 | E6: 6 | F6: 10
B7: Small | C7: All other Agents | D7: 2 | E7: 6 | F7: 10
B8: Small | C8: Database | D8: 8 | E8: 32 | F8: 20
B9: Small | C9: CP4D Base | D9: 3 | E9: 4 | F9: 20
B10: Medium | C10: UI App Server / Data Import Agent | D10: 2 | E10: 6 | F10: 10
B11: Medium | C11: UI App Server / Data Import Agent | D11: 2 | E11: 6 | F11: 10
B12: Medium | C12: UI App Server / Data Import Agent | D12: 2 | E12: 6 | F12: 10
B13: Medium | C13: WF Agent | D13: 4 | E13: 6 | F13: 10
B14: Medium | C14: Report Queue Agent | D14: 4 | E14: 6 | F14: 10
B15: Medium | C15: All other Agents | D15: 2 | E15: 6 | F15: 10
B16: Medium | C16: Database | D16: 12 | E16: 48 | F16: 500
... B35: Large | C35: CP4D Base | D35: 3 | E35: 4 | F35: 20

Sheet Versions
C1: Version | D1: Updates
C2: v11_5 | D2: New Calculator - Major Update - Many Changes
C3: v11_5.1 | D3: made calculations a bit more granular for later needs
C4: v11_5.2 | D4: Updated Database Calculations
C5: v9.1 | D5: Changed to support Maximo Real Estate and Facilities 9.1
C7: v9.1 | D7: Rebaselined to support Maximo Real Estate and Facilities 9.1
